<!-- -*- mode: xml -*- -->

<robot name="downscale">
  <!-- Import Rviz colors -->
  <material name="Grey">
    <color rgba="0.2 0.2 0.2 1.0"/>
  </material>
  <material name="Orange">
    <color rgba="1.0 0.423529411765 0.0392156862745 1.0"/>
  </material>
  <material name="Blue">
    <color rgba="0.5 0.7 1.0 1.0"/> 
  </material>
  <material name="White">
    <color rgba="1.0 1.0 1.0 1.0"/>  
  </material>
  <material name="LightGrey">
    <color rgba="0.7 0.7 0.7 1.0"/>        
  </material>	

  <link
    name="base">
    <inertial>
      <origin
        xyz="-9.0846E-05 -1.5683E-05 0.15321"
        rpy="0 0 0" />
      <mass
        value="7.0213" />
      <inertia
        ixx="0.020091"
        ixy="7.7565E-07"
        ixz="-6.9172E-06"
        iyy="0.019264"
        iyz="-6.3097E-06"
        izz="0.02593" />
    </inertial>
    <visual>
      <origin
        xyz="0 0 0"
        rpy="0 0 0" />
      <geometry>
        <mesh
          filename="package://meshes/base_v1.STL" />
      </geometry>
      <material name="LightGrey"/>
    </visual>
    <collision>
      <origin
        xyz="0 0 0"
        rpy="0 0 0" />
      <geometry>
        <mesh
          filename="package://meshes/base_v1.STL" />
      </geometry>
    </collision>
  </link>
  <link
    name="L1">
    <inertial>
      <origin
        xyz="-5.5429E-07 0.12272 0.0034643"
        rpy="0 0 0" />
      <mass
        value="8.2118" />
      <inertia
        ixx="0.018432"
        ixy="-2.5642E-07"
        ixz="-2.8054E-08"
        iyy="0.01779"
        iyz="0.00019144"
        izz="0.028013" />
    </inertial>
    <visual>
      <origin
        xyz="0 0 0"
        rpy="0 0 0" />
      <geometry>
        <mesh
          filename="package://meshes/L1_v1.STL" />
      </geometry>
      <material name="Orange"/>
    </visual>
    <collision>
      <origin
        xyz="0 0 0"
        rpy="0 0 0" />
      <geometry>
        <mesh
          filename="package://meshes/L1_v1.STL" />
      </geometry>
    </collision>
  </link>
  <joint
    name="J1"
    type="revolute">
    <origin
      xyz="0 0 0.234"
      rpy="1.5708 0 0" />
    <parent
      link="base" />
    <child
      link="L1" />
    <axis
      xyz="0 1 0" />
    <limit
      lower="-3.14159"
      upper="3.14159"
      effort="300"
      velocity="1" />
    <dynamics
      damping="0.5"
      friction="0.1" />
  </joint>
  <link
    name="L2">
    <inertial>
      <origin
        xyz="-1.67E-05 -0.0027964 0.21973"
        rpy="0 0 0" />
      <mass
        value="7.0254" />
      <inertia
        ixx="0.015046"
        ixy="4.9882E-06"
        ixz="-7.5466E-06"
        iyy="0.015815"
        iyz="9.8904E-05"
        izz="0.013986" />
    </inertial>
    <visual>
      <origin
        xyz="0 0 0"
        rpy="0 0 0" />
      <geometry>
        <mesh
          filename="package://meshes/L2_v1.STL" />
      </geometry>
      <material name="LightGrey"/>
    </visual>
    <collision>
      <origin
        xyz="0 0 0"
        rpy="0 0 0" />
      <geometry>
        <mesh
          filename="package://meshes/L2_v1.STL" />
      </geometry>
    </collision>
  </link>
  <joint
    name="J2"
    type="revolute">
    <origin
      xyz="0 0.165 0"
      rpy="-1.5708 0 0" />
    <parent
      link="L1" />
    <child
      link="L2" />
    <axis
      xyz="0 1 0" />
    <limit
      lower="-1.91986"
      upper="1.91986"
      effort="300"
      velocity="1" />
    <dynamics
      damping="0.5"
      friction="0.1" />
  </joint>
  <link
    name="L3">
    <inertial>
      <origin
        xyz="2.6383E-05 0.12013 -0.01005"
        rpy="0 0 0" />
      <mass
        value="4.6088" />
      <inertia
        ixx="0.0075222"
        ixy="4.7134E-06"
        ixz="7.566E-06"
        iyy="0.0067469"
        iyz="6.777E-05"
        izz="0.011218" />
    </inertial>
    <visual>
      <origin
        xyz="0 0 0"
        rpy="0 0 0" />
      <geometry>
        <mesh
          filename="package://meshes/L3.STL" />
      </geometry>
      <material name="Orange"/>
    </visual>
    <collision>
      <origin
        xyz="0 0 0"
        rpy="0 0 0" />
      <geometry>
        <mesh
          filename="package://meshes/L3.STL" />
      </geometry>
    </collision>
  </link>
  <joint
    name="J3"
    type="revolute">
    <origin
      xyz="0 0 0.398"
      rpy="1.5708 0 0" />
    <parent
      link="L2" />
    <child
      link="L3" />
    <axis
      xyz="0 1 0" />
    <limit
      lower="-3.14159"
      upper="3.14159"
      effort="300"
      velocity="1" />
    <dynamics
      damping="0.5"
      friction="0.1" />
  </joint>
  <link
    name="L4">
    <inertial>
      <origin
        xyz="2.6191E-05 0.0003359 0.1968"
        rpy="0 0 0" />
      <mass
        value="4.2606" />
      <inertia
        ixx="0.0070555"
        ixy="4.6581E-06"
        ixz="6.4804E-06"
        iyy="0.0072718"
        iyz="-5.3344E-05"
        izz="0.0058033" />
    </inertial>
    <visual>
      <origin
        xyz="0 0 0"
        rpy="0 0 0" />
      <geometry>
        <mesh
          filename="package://meshes/L4_v1.STL" />
      </geometry>
      <material name="LightGrey"/>
    </visual>
    <collision>
      <origin
        xyz="0 0 0"
        rpy="0 0 0" />
      <geometry>
        <mesh
          filename="package://meshes/L4_v1.STL" />
      </geometry>
    </collision>
  </link>
  <joint
    name="J4"
    type="revolute">
    <origin
      xyz="0 0.149 0"
      rpy="1.5708 0 -3.1416" />
    <parent
      link="L3" />
    <child
      link="L4" />
    <axis
      xyz="0 1 0" />
    <limit
      lower="-2.61799"
      upper="2.61799"
      effort="300"
      velocity="1" />
    <dynamics
      damping="0.5"
      friction="0.1" />
  </joint>
  <link
    name="L5">
    <inertial>
      <origin
        xyz="6.2467E-05 0.095372 -0.019881"
        rpy="0 0 0" />
      <mass
        value="2.3502" />
      <inertia
        ixx="0.0024625"
        ixy="4.5124E-06"
        ixz="6.4726E-06"
        iyy="0.0022429"
        iyz="2.6835E-05"
        izz="0.003385" />
    </inertial>
    <visual>
      <origin
        xyz="0 0 0"
        rpy="0 0 0" />
      <geometry>
        <mesh
          filename="package://meshes/L5_v1.STL" />
      </geometry>
      <material name="Orange"/>
    </visual>
    <collision>
      <origin
        xyz="0 0 0"
        rpy="0 0 0" />
      <geometry>
        <mesh
          filename="package://meshes/L5_v1.STL" />
      </geometry>
    </collision>
  </link>
  <joint
    name="J5"
    type="revolute">
    <origin
      xyz="0 0 0.363"
      rpy="1.5708 0 3.1416" />
    <parent
      link="L4" />
    <child
      link="L5" />
    <axis
      xyz="0 1 0" />
    <limit
      lower="-3.14159"
      upper="3.14159"
      effort="300"
      velocity="1" />
    <dynamics
      damping="0.1"
      friction="0.1" />
  </joint>
  <link
    name="L6">
    <inertial>
      <origin
        xyz="-2.021E-05 -0.0023656 0.15181"
        rpy="0 0 0" />
      <mass
        value="2.495" />
      <inertia
        ixx="0.0047154"
        ixy="-6.7153E-07"
        ixz="2.6191E-07"
        iyy="0.0049704"
        iyz="1.2591E-05"
        izz="0.0026264" />
    </inertial>
    <visual>
      <origin
        xyz="0 0 0"
        rpy="0 0 0" />
      <geometry>
        <mesh
          filename="package://meshes/L6_v1.STL" />
      </geometry>
      <material name="LightGrey"/>
    </visual>
    <collision>
      <origin
        xyz="0 0 0"
        rpy="0 0 0" />
      <geometry>
        <mesh
          filename="package://meshes/L6_v1.STL" />
      </geometry>
    </collision>
  </link>
  <joint
    name="J6"
    type="revolute">
    <origin
      xyz="0 0.121 0"
      rpy="-1.5708 0 0" />
    <parent
      link="L5" />
    <child
      link="L6" />
    <axis
      xyz="0 1 0" />
    <limit
      lower="-1.91986"
      upper="1.91986"
      effort="300"
      velocity="1" />
    <dynamics
      damping="0.5"
      friction="0.1" />
  </joint>
  <link
    name="L7">
    <inertial>
      <origin
        xyz="-1.836E-07 0.072275 1.2326E-08"
        rpy="0 0 0" />
      <mass
        value="0.36882" />
      <inertia
        ixx="0.00017028"
        ixy="3.6031E-11"
        ixz="4.7086E-10"
        iyy="0.00022228"
        iyz="-6.1886E-11"
        izz="0.00016383" />
    </inertial>
    <visual>
      <origin
        xyz="0 0 0"
        rpy="0 0 0" />
      <geometry>
        <mesh
          filename="package://meshes/L7_v1.STL" />
      </geometry>
      <material name="Orange"/>
    </visual>
    <collision>
      <origin
        xyz="0 0 0"
        rpy="0 0 0" />
      <geometry>
        <mesh
          filename="package://meshes/L7_v1.STL" />
      </geometry>
    </collision>
  </link>
  <joint
    name="J7"
    type="revolute">
    <origin
      xyz="0 0 0.273"
      rpy="1.5708 0 -1.5647" />
    <parent
      link="L6" />
    <child
      link="L7" />
    <axis
      xyz="0 1 0" />
    <limit
      lower="-3.14159"
      upper="3.14159"
      effort="300"
      velocity="1" />
    <dynamics
      damping="0.5"
      friction="0.1" />
  </joint>
</robot>
